Workbook

Sheet Current Screen Template
A1: Identifier | B1: Company Name | C1: Country of Exchange | D1: ESG Score In the last 7 FY
D2: FY0 | E2: FY-1 | F2: FY-2 | G2: FY-3 | H2: FY-4 | I2: FY-5 | J2: FY-6
D3: 3 | E3: 4 | F3: 5 | G3: 6 | H3: 7 | I3: 8 | J3: 9
A4: BBDC4.SA | B4: Banco Bradesco SA | C4: Brazil | D4: 80.020666 | E4: 78.71582 | F4: 78.287742 | G4: 80.682857 | H4: 79.130292 | I4: 79.715794 | J4: 78.963626
A5: ALPA4.SA | B5: Alpargatas SA | C5: Brazil | D5: 68.403876 | E5: 63.911547 | F5: 24.287392 | G5: 15.902739 | H5: 0 | I5: 0 | J5: 0
A6: LIGT3.SA | B6: Light SA | C6: Brazil | D6: 58.902045 | E6: 67.045989 | F6: 62.840993 | G6: 58.580844 | H6: 61.973786 | I6: 63.152152 | J6: 68.257282
A7: BRKM5.SA | B7: Braskem SA | C7: Brazil | D7: 50.954448 | E7: 53.749306 | F7: 55.824727 | G7: 55.398994 | H7: 53.848717 | I7: 59.019721 | J7: 57.890234
A8: ITUB4.SA | B8: Itau Unibanco Holding SA | C8: Brazil | D8: 84.815144 | E8: 87.827648 | F8: 89.424348 | G8: 87.638328 | H8: 89.504634 | I8: 89.820081 | J8: 89.135771
A9: LEVE3.SA | B9: MAHLE Metal Leve SA | C9: Brazil | D9: 34.944956 | E9: 31.88867 | F9: 32.932458 | G9: 25.996886 | H9: 25.523087 | I9: 0 | J9: 0
A10: CMIG4.SA | B10: Energy of Minas Gerais Co | C10: Brazil | D10: 75.07793 | E10: 74.888942 | F10: 72.332879 | G10: 75.134662 | H10: 76.761129 | I10: 74.061487 | J10: 70.332571
A11: ELET6.SA | B11: Centrais Eletricas Brasileiras SA - Eletrobras | C11: Brazil | D11: 71.756169 | E11: 69.951089 | F11: 81.713065 | G11: 80.023443 | H11: 79.279765 | I11: 74.516473 | J11: 67.624051
A12: BRFS3.SA | B12: BRF SA | C12: Brazil | D12: 81.376649 | E12: 82.30215 | F12: 81.664039 | G12: 78.244562 | H12: 77.482697 | I12: 73.206153 | J12: 74.215601
A13: VALE3.SA | B13: Vale SA | C13: Brazil | D13: 88.956899 | E13: 89.450592 | F13: 89.842715 | G13: 90.367998 | H13: 86.228756 | I13: 82.419393 | J13: 80.585822
A14: PETR4.SA | B14: Petroleo Brasileiro SA Petrobras | C14: Brazil | D14: 72.641536 | E14: 75.391845 | F14: 75.315699 | G14: 74.370008 | H14: 73.3739 | I14: 74.564112 | J14: 75.603566
A15: UNIP6.SA | B15: Unipar Carbocloro SA | C15: Brazil | D15: 17.351787 | E15: 23.365131 | F15: 0 | G15: 0 | H15: 0 | I15: 0 | J15: 0
... A2173: BOGr.AT | B2173: Bank of Greece | C2173: Greece | D2173: 2.9209793 | E2173: 2.9828889 | F2173: 2.5721528 | G2173: 2.6215482 | H2173: 1.6137423 | I2173: 1.7778911 | J2173: 2.31609

Sheet Data processed
A1: No | B1: Identifier | C1: Company Name | D1: Country of exchange | E1: ESG Score | F1: Formula | G1: Value
A2: 1 | B2: BBDC4.SA | C2: Banco Bradesco SA | D2: Brazil | E2: FY0 | F2: =VLOOKUP(C2,'Current Screen Template'!$B:$J,3,FALSE) -> 80.020666 | G2: 80.02
A3: 1 | B3: BBDC4.SA | C3: Banco Bradesco SA | D3: Brazil | E3: FY-1 | F3: =VLOOKUP(C3,'Current Screen Template'!$B:$J,4,FALSE) -> 78.71582 | G3: 78.72
A4: 1 | B4: BBDC4.SA | C4: Banco Bradesco SA | D4: Brazil | E4: FY-2 | F4: =VLOOKUP(C4,'Current Screen Template'!$B:$J,5,FALSE) -> 78.287742 | G4: 78.29
A5: 1 | B5: BBDC4.SA | C5: Banco Bradesco SA | D5: Brazil | E5: FY-3 | F5: =VLOOKUP(C5,'Current Screen Template'!$B:$J,6,FALSE) -> 80.682857 | G5: 80.68
A6: 1 | B6: BBDC4.SA | C6: Banco Bradesco SA | D6: Brazil | E6: FY-4 | F6: =VLOOKUP(C6,'Current Screen Template'!$B:$J,7,FALSE) -> 79.130292 | G6: 79.13
A7: 1 | B7: BBDC4.SA | C7: Banco Bradesco SA | D7: Brazil | E7: FY-5 | F7: =VLOOKUP(C7,'Current Screen Template'!$B:$J,8,FALSE) -> 79.715794 | G7: 79.72
A8: 1 | B8: BBDC4.SA | C8: Banco Bradesco SA | D8: Brazil | E8: FY-6 | F8: =VLOOKUP(C8,'Current Screen Template'!$B:$J,9,FALSE) -> 78.963626 | G8: 78.96
A9: 2 | B9: ALPA4.SA | C9: Alpargatas SA | D9: Brazil | E9: FY0 | F9: =VLOOKUP(C9,'Current Screen Template'!$B:$J,3,FALSE) -> 68.403876 | G9: 68.4
A10: 2 | B10: ALPA4.SA | C10: Alpargatas SA | D10: Brazil | E10: FY-1 | F10: =VLOOKUP(C10,'Current Screen Template'!$B:$J,4,FALSE) -> 63.911547 | G10: 63.91
A11: 2 | B11: ALPA4.SA | C11: Alpargatas SA | D11: Brazil | E11: FY-2 | F11: =VLOOKUP(C11,'Current Screen Template'!$B:$J,5,FALSE) -> 24.287392 | G11: 24.29
A12: 2 | B12: ALPA4.SA | C12: Alpargatas SA | D12: Brazil | E12: FY-3 | F12: =VLOOKUP(C12,'Current Screen Template'!$B:$J,6,FALSE) -> 15.902739 | G12: 15.9
A13: 2 | B13: ALPA4.SA | C13: Alpargatas SA | D13: Brazil | E13: FY-4 | F13: =VLOOKUP(C9,'Current Screen Template'!$B:$J,7,FALSE) -> 0 | G13: 0
A14: 2 | B14: ALPA4.SA | C14: Alpargatas SA | D14: Brazil | E14: FY-5 | F14: =VLOOKUP(C14,'Current Screen Template'!$B:$J,8,FALSE) -> 0 | G14: 0
A15: 2 | B15: ALPA4.SA | C15: Alpargatas SA | D15: Brazil | E15: FY-6 | F15: =VLOOKUP(C15,'Current Screen Template'!$B:$J,9,FALSE) -> 0 | G15: 0
A16: 3 | B16: LIGT3.SA | C16: Light SA | D16: Brazil | E16: FY0 | F16: =VLOOKUP(C16,'Current Screen Template'!$B:$J,3,FALSE) -> 58.902045 | G16: 58.9
A17: 3 | B17: LIGT3.SA | C17: Light SA | D17: Brazil | E17: FY-1 | F17: =VLOOKUP(C17,'Current Screen Template'!$B:$J,4,FALSE) -> 67.045989 | G17: 67.05
A18: 3 | B18: LIGT3.SA | C18: Light SA | D18: Brazil | E18: FY-2 | F18: =VLOOKUP(C18,'Current Screen Template'!$B:$J,5,FALSE) -> 62.840993 | G18: 62.84
A19: 3 | B19: LIGT3.SA | C19: Light SA | D19: Brazil | E19: FY-3 | F19: =VLOOKUP(C19,'Current Screen Template'!$B:$J,6,FALSE) -> 58.580844 | G19: 58.58
A20: 3 | B20: LIGT3.SA | C20: Light SA | D20: Brazil | E20: FY-4 | F20: =VLOOKUP(C16,'Current Screen Template'!$B:$J,7,FALSE) -> 61.973786 | G20: 61.97
A21: 3 | B21: LIGT3.SA | C21: Light SA | D21: Brazil | E21: FY-5 | F21: =VLOOKUP(C21,'Current Screen Template'!$B:$J,8,FALSE) -> 63.152152 | G21: 63.15
A22: 3 | B22: LIGT3.SA | C22: Light SA | D22: Brazil | E22: FY-6 | F22: =VLOOKUP(C22,'Current Screen Template'!$B:$J,9,FALSE) -> 68.257282 | G22: 68.26
A23: 4 | B23: BRKM5.SA | C23: Braskem SA | D23: Brazil | E23: FY0 | F23: =VLOOKUP(C23,'Current Screen Template'!$B:$J,3,FALSE) -> 50.954448 | G23: 50.95
A24: 4 | B24: BRKM5.SA | C24: Braskem SA | D24: Brazil | E24: FY-1 | F24: =VLOOKUP(C24,'Current Screen Template'!$B:$J,4,FALSE) -> 53.749306 | G24: 53.75
A25: 4 | B25: BRKM5.SA | C25: Braskem SA | D25: Brazil | E25: FY-2 | F25: =VLOOKUP(C25,'Current Screen Template'!$B:$J,5,FALSE) -> 55.824727 | G25: 55.82
A26: 4 | B26: BRKM5.SA | C26: Braskem SA | D26: Brazil | E26: FY-3 | F26: =VLOOKUP(C26,'Current Screen Template'!$B:$J,6,FALSE) -> 55.398994 | G26: 55.4
A27: 4 | B27: BRKM5.SA | C27: Braskem SA | D27: Brazil | E27: FY-4 | F27: =VLOOKUP(C23,'Current Screen Template'!$B:$J,7,FALSE) -> 53.848717 | G27: 53.85
A28: 4 | B28: BRKM5.SA | C28: Braskem SA | D28: Brazil | E28: FY-5 | F28: =VLOOKUP(C28,'Current Screen Template'!$B:$J,8,FALSE) -> 59.019721 | G28: 59.02
A29: 4 | B29: BRKM5.SA | C29: Braskem SA | D29: Brazil | E29: FY-6 | F29: =VLOOKUP(C29,'Current Screen Template'!$B:$J,9,FALSE) -> 57.890234 | G29: 57.89
A30: 5 | B30: ITUB4.SA | C30: Itau Unibanco Holding SA | D30: Brazil | E30: FY0 | F30: =VLOOKUP(C30,'Current Screen Template'!$B:$J,3,FALSE) -> 84.815144 | G30: 84.82
A31: 5 | B31: ITUB4.SA | C31: Itau Unibanco Holding SA | D31: Brazil | E31: FY-1 | F31: =VLOOKUP(C31,'Current Screen Template'!$B:$J,4,FALSE) -> 87.827648 | G31: 87.83
A32: 5 | B32: ITUB4.SA | C32: Itau Unibanco Holding SA | D32: Brazil | E32: FY-2 | F32: =VLOOKUP(C32,'Current Screen Template'!$B:$J,5,FALSE) -> 89.424348 | G32: 89.42
A33: 5 | B33: ITUB4.SA | C33: Itau Unibanco Holding SA | D33: Brazil | E33: FY-3 | F33: =VLOOKUP(C33,'Current Screen Template'!$B:$J,6,FALSE) -> 87.638328 | G33: 87.64
A34: 5 | B34: ITUB4.SA | C34: Itau Unibanco Holding SA | D34: Brazil | E34: FY-4 | F34: =VLOOKUP(C30,'Current Screen Template'!$B:$J,7,FALSE) -> 89.504634 | G34: 89.5
A35: 5 | B35: ITUB4.SA | C35: Itau Unibanco Holding SA | D35: Brazil | E35: FY-5 | F35: =VLOOKUP(C35,'Current Screen Template'!$B:$J,8,FALSE) -> 89.820081 | G35: 89.82
A36: 5 | B36: ITUB4.SA | C36: Itau Unibanco Holding SA | D36: Brazil | E36: FY-6 | F36: =VLOOKUP(C36,'Current Screen Template'!$B:$J,9,FALSE) -> 89.135771 | G36: 89.14
A37: 6 | B37: LEVE3.SA | C37: MAHLE Metal Leve SA | D37: Brazil | E37: FY0 | F37: =VLOOKUP(C37,'Current Screen Template'!$B:$J,3,FALSE) -> 34.944956 | G37: 34.94
A38: 6 | B38: LEVE3.SA | C38: MAHLE Metal Leve SA | D38: Brazil | E38: FY-1 | F38: =VLOOKUP(C38,'Current Screen Template'!$B:$J,4,FALSE) -> 31.88867 | G38: 31.89
A39: 6 | B39: LEVE3.SA | C39: MAHLE Metal Leve SA | D39: Brazil | E39: FY-2 | F39: =VLOOKUP(C39,'Current Screen Template'!$B:$J,5,FALSE) -> 32.932458 | G39: 32.93
A40: 6 | B40: LEVE3.SA | C40: MAHLE Metal Leve SA | D40: Brazil | E40: FY-3 | F40: =VLOOKUP(C40,'Current Screen Template'!$B:$J,6,FALSE) -> 25.996886 | G40: 26
...
